2025-05-01 23:52:51,586 - INFO - Loading model: meta-llama/Llama-2-7b-hf
2025-05-01 23:52:51,587 - INFO - Loading model from: meta-llama/Llama-2-7b-hf
/u/home/x/xxiong/miniforge3/envs/modegpt/lib/python3.10/site-packages/huggingface_hub/file_download.py:896: FutureWarning: `resume_download` is deprecated and will be removed in version 1.0.0. Downloads always resume when possible. If you want to force a new download, use `force_download=True`.
  warnings.warn(
2025-05-01 23:52:54,176 - ERROR - [Error] Failed to load model meta-llama/Llama-2-7b-hf: You are trying to access a gated repo.
Make sure to have access to it at https://huggingface.co/meta-llama/Llama-2-7b-hf.
401 Client Error. (Request ID: Root=1-68146bc6-403d86e75cb8fdcf71b27108;91582702-7339-4b7b-93c9-d541ad2498b0)

Cannot access gated repo for url https://huggingface.co/meta-llama/Llama-2-7b-hf/resolve/main/config.json.
Access to model meta-llama/Llama-2-7b-hf is restricted. You must have access to it and be authenticated to access it. Please log in.
Traceback (most recent call last):
  File "/u/home/x/xxiong/miniforge3/envs/modegpt/lib/python3.10/site-packages/huggingface_hub/utils/_http.py", line 409, in hf_raise_for_status
    response.raise_for_status()
  File "/u/home/x/xxiong/miniforge3/envs/modegpt/lib/python3.10/site-packages/requests/models.py", line 1024, in raise_for_status
    raise HTTPError(http_error_msg, response=self)
requests.exceptions.HTTPError: 401 Client Error: Unauthorized for url: https://huggingface.co/meta-llama/Llama-2-7b-hf/resolve/main/config.json

The above exception was the direct cause of the following exception:

Traceback (most recent call last):
  File "/u/home/x/xxiong/miniforge3/envs/modegpt/lib/python3.10/site-packages/transformers/utils/hub.py", line 399, in cached_file
    resolved_file = hf_hub_download(
  File "/u/home/x/xxiong/miniforge3/envs/modegpt/lib/python3.10/site-packages/huggingface_hub/utils/_validators.py", line 114, in _inner_fn
    return fn(*args, **kwargs)
  File "/u/home/x/xxiong/miniforge3/envs/modegpt/lib/python3.10/site-packages/huggingface_hub/file_download.py", line 961, in hf_hub_download
    return _hf_hub_download_to_cache_dir(
  File "/u/home/x/xxiong/miniforge3/envs/modegpt/lib/python3.10/site-packages/huggingface_hub/file_download.py", line 1068, in _hf_hub_download_to_cache_dir
    _raise_on_head_call_error(head_call_error, force_download, local_files_only)
  File "/u/home/x/xxiong/miniforge3/envs/modegpt/lib/python3.10/site-packages/huggingface_hub/file_download.py", line 1596, in _raise_on_head_call_error
    raise head_call_error
  File "/u/home/x/xxiong/miniforge3/envs/modegpt/lib/python3.10/site-packages/huggingface_hub/file_download.py", line 1484, in _get_metadata_or_catch_error
    metadata = get_hf_file_metadata(
  File "/u/home/x/xxiong/miniforge3/envs/modegpt/lib/python3.10/site-packages/huggingface_hub/utils/_validators.py", line 114, in _inner_fn
    return fn(*args, **kwargs)
  File "/u/home/x/xxiong/miniforge3/envs/modegpt/lib/python3.10/site-packages/huggingface_hub/file_download.py", line 1401, in get_hf_file_metadata
    r = _request_wrapper(
  File "/u/home/x/xxiong/miniforge3/envs/modegpt/lib/python3.10/site-packages/huggingface_hub/file_download.py", line 285, in _request_wrapper
    response = _request_wrapper(
  File "/u/home/x/xxiong/miniforge3/envs/modegpt/lib/python3.10/site-packages/huggingface_hub/file_download.py", line 309, in _request_wrapper
    hf_raise_for_status(response)
  File "/u/home/x/xxiong/miniforge3/envs/modegpt/lib/python3.10/site-packages/huggingface_hub/utils/_http.py", line 426, in hf_raise_for_status
    raise _format(GatedRepoError, message, response) from e
huggingface_hub.errors.GatedRepoError: 401 Client Error. (Request ID: Root=1-68146bc6-403d86e75cb8fdcf71b27108;91582702-7339-4b7b-93c9-d541ad2498b0)

Cannot access gated repo for url https://huggingface.co/meta-llama/Llama-2-7b-hf/resolve/main/config.json.
Access to model meta-llama/Llama-2-7b-hf is restricted. You must have access to it and be authenticated to access it. Please log in.

The above exception was the direct cause of the following exception:

Traceback (most recent call last):
  File "/u/home/x/xxiong/MoDeGPT/run_modegpt.py", line 355, in <module>
    main()
  File "/u/home/x/xxiong/MoDeGPT/run_modegpt.py", line 237, in main
    model, tokenizer, config = load_model(args.model, device=device)
  File "/u/home/x/xxiong/MoDeGPT/model_utils.py", line 159, in load_model
    tokenizer = AutoTokenizer.from_pretrained(model_name)
  File "/u/home/x/xxiong/miniforge3/envs/modegpt/lib/python3.10/site-packages/transformers/models/auto/tokenization_auto.py", line 837, in from_pretrained
    config = AutoConfig.from_pretrained(
  File "/u/home/x/xxiong/miniforge3/envs/modegpt/lib/python3.10/site-packages/transformers/models/auto/configuration_auto.py", line 934, in from_pretrained
    config_dict, unused_kwargs = PretrainedConfig.get_config_dict(pretrained_model_name_or_path, **kwargs)
  File "/u/home/x/xxiong/miniforge3/envs/modegpt/lib/python3.10/site-packages/transformers/configuration_utils.py", line 632, in get_config_dict
    config_dict, kwargs = cls._get_config_dict(pretrained_model_name_or_path, **kwargs)
  File "/u/home/x/xxiong/miniforge3/envs/modegpt/lib/python3.10/site-packages/transformers/configuration_utils.py", line 689, in _get_config_dict
    resolved_config_file = cached_file(
  File "/u/home/x/xxiong/miniforge3/envs/modegpt/lib/python3.10/site-packages/transformers/utils/hub.py", line 417, in cached_file
    raise EnvironmentError(
OSError: You are trying to access a gated repo.
Make sure to have access to it at https://huggingface.co/meta-llama/Llama-2-7b-hf.
401 Client Error. (Request ID: Root=1-68146bc6-403d86e75cb8fdcf71b27108;91582702-7339-4b7b-93c9-d541ad2498b0)

Cannot access gated repo for url https://huggingface.co/meta-llama/Llama-2-7b-hf/resolve/main/config.json.
Access to model meta-llama/Llama-2-7b-hf is restricted. You must have access to it and be authenticated to access it. Please log in.
